Workbook

Sheet Leyenda
A1: Matriz de trazabilidad · Mundo de Fe México
A2: Base: documentos v3 y v3.2 (MVP). Versión 1.0 de la matriz · borrador para VoBo.
A4: Cómo usarla
A5: Hoja Matriz | B5: Una fila por requerimiento. Las columnas A a H salen de los documentos; I y J son un borrador de historia y criterio de aceptación para lo que entra al MVP. Completa K, L y M durante el desarrollo.
A6: Hoja Observaciones | B6: Rastrea cada observación del v3 hacia los requerimientos que la atienden.
A7: Hoja Origen v1 | B7: Rastrea cada necesidad del levantamiento original (v1) hacia los requerimientos actuales; sirve para detectar pérdidas entre versiones.
A8: Hoja Resumen | B8: Avance por fase, hito y estado. Se calcula con fórmulas a partir de la hoja Matriz: no se edita.
A9: Columnas editables
A10: Estado | B10: Elige de la lista: Pendiente, En diseño, En desarrollo, En pruebas, Hecho, Bloqueado. Ejemplo: En pruebas.
A11: Evidencia | B11: Enlace o referencia que demuestra el avance (rama, pantalla del lienzo, resultado de la prueba). Ejemplo: Rama feature/m1-17-acceso · Prueba P-017 aprobada.
A12: Notas | B12: Dudas, decisiones y cambios al requerimiento. Ejemplo: 2026-10-10 · PIN de 6 dígitos confirmado con el Pastor.
A13: Hitos
A14: H1 · 18-oct (núcleo Fase 0) | B14: Objetivo para el 18 de octubre: acceso con WhatsApp + PIN, expediente (EDU) y Contacto, consentimiento, roles base, bitácora, respaldos y despliegue. Es un núcleo, no la Fase 0 completa.
A15: H2 · Fase 0 completa | B15: Avisos y notificaciones, plantillas, diseñador de formularios, permisos por área, seguimiento a visitantes y catálogo de áreas. Estimado: unas 3 semanas después de H1 si se mantiene el ritmo (estimación mía, a recalibrar).
A16: H3 · MVP (Grupos) | B16: Módulo Grupos de Conexión completo, pase de lista sin conexión y dashboards.
A17: Posterior | B17: Fases 2 a 5: Kids, Cursos, Áreas completas, Ministerios, Eventos, vehículos y app nativa.
A18: Origen (colores)
A19: Verde | B19: Recuperado del levantamiento original (v1).
A20: Amarillo | B20: Nuevo o corregido en versiones posteriores (observaciones, respuestas, v3.1 o v3.2).

Sheet Resumen
A1: Resumen de avance
A2: Se calcula con fórmulas a partir de la hoja Matriz. No editar.
A4: Fase | B4: Total | C4: Pendiente | D4: En diseño | E4: En desarrollo | F4: En pruebas | G4: Hecho | H4: Bloqueado | I4: % Hecho
A5: Fase 0 | B5: =COUNTIF(Matriz!$F$2:$F$105,$A5) | C5: =COUNTIFS(Matriz!$F$2:$F$105,$A5,Matriz!$L$2:$L$105,"Pendiente") | D5: =COUNTIFS(Matriz!$F$2:$F$105,$A5,Matriz!$L$2:$L$105,"En diseño") | E5: =COUNTIFS(Matriz!$F$2:$F$105,$A5,Matriz!$L$2:$L$105,"En desarrollo") | F5: =COUNTIFS(Matriz!$F$2:$F$105,$A5,Matriz!$L$2:$L$105,"En pruebas") | G5: =COUNTIFS(Matriz!$F$2:$F$105,$A5,Matriz!$L$2:$L$105,"Hecho") | H5: =COUNTIFS(Matriz!$F$2:$F$105,$A5,Matriz!$L$2:$L$105,"Bloqueado") | I5: =IF(B5=0,0,G5/B5)
A6: Fase 1 | B6: =COUNTIF(Matriz!$F$2:$F$105,$A6) | C6: =COUNTIFS(Matriz!$F$2:$F$105,$A6,Matriz!$L$2:$L$105,"Pendiente") | D6: =COUNTIFS(Matriz!$F$2:$F$105,$A6,Matriz!$L$2:$L$105,"En diseño") | E6: =COUNTIFS(Matriz!$F$2:$F$105,$A6,Matriz!$L$2:$L$105,"En desarrollo") | F6: =COUNTIFS(Matriz!$F$2:$F$105,$A6,Matriz!$L$2:$L$105,"En pruebas") | G6: =COUNTIFS(Matriz!$F$2:$F$105,$A6,Matriz!$L$2:$L$105,"Hecho") | H6: =COUNTIFS(Matriz!$F$2:$F$105,$A6,Matriz!$L$2:$L$105,"Bloqueado") | I6: =IF(B6=0,0,G6/B6)
A7: Fase 2 | B7: =COUNTIF(Matriz!$F$2:$F$105,$A7) | C7: =COUNTIFS(Matriz!$F$2:$F$105,$A7,Matriz!$L$2:$L$105,"Pendiente") | D7: =COUNTIFS(Matriz!$F$2:$F$105,$A7,Matriz!$L$2:$L$105,"En diseño") | E7: =COUNTIFS(Matriz!$F$2:$F$105,$A7,Matriz!$L$2:$L$105,"En desarrollo") | F7: =COUNTIFS(Matriz!$F$2:$F$105,$A7,Matriz!$L$2:$L$105,"En pruebas") | G7: =COUNTIFS(Matriz!$F$2:$F$105,$A7,Matriz!$L$2:$L$105,"Hecho") | H7: =COUNTIFS(Matriz!$F$2:$F$105,$A7,Matriz!$L$2:$L$105,"Bloqueado") | I7: =IF(B7=0,0,G7/B7)
A8: Fase 3 | B8: =COUNTIF(Matriz!$F$2:$F$105,$A8) | C8: =COUNTIFS(Matriz!$F$2:$F$105,$A8,Matriz!$L$2:$L$105,"Pendiente") | D8: =COUNTIFS(Matriz!$F$2:$F$105,$A8,Matriz!$L$2:$L$105,"En diseño") | E8: =COUNTIFS(Matriz!$F$2:$F$105,$A8,Matriz!$L$2:$L$105,"En desarrollo") | F8: =COUNTIFS(Matriz!$F$2:$F$105,$A8,Matriz!$L$2:$L$105,"En pruebas") | G8: =COUNTIFS(Matriz!$F$2:$F$105,$A8,Matriz!$L$2:$L$105,"Hecho") | H8: =COUNTIFS(Matriz!$F$2:$F$105,$A8,Matriz!$L$2:$L$105,"Bloqueado") | I8: =IF(B8=0,0,G8/B8)
A9: Fase 4 | B9: =COUNTIF(Matriz!$F$2:$F$105,$A9) | C9: =COUNTIFS(Matriz!$F$2:$F$105,$A9,Matriz!$L$2:$L$105,"Pendiente") | D9: =COUNTIFS(Matriz!$F$2:$F$105,$A9,Matriz!$L$2:$L$105,"En diseño") | E9: =COUNTIFS(Matriz!$F$2:$F$105,$A9,Matriz!$L$2:$L$105,"En desarrollo") | F9: =COUNTIFS(Matriz!$F$2:$F$105,$A9,Matriz!$L$2:$L$105,"En pruebas") | G9: =COUNTIFS(Matriz!$F$2:$F$105,$A9,Matriz!$L$2:$L$105,"Hecho") | H9: =COUNTIFS(Matriz!$F$2:$F$105,$A9,Matriz!$L$2:$L$105,"Bloqueado") | I9: =IF(B9=0,0,G9/B9)
A10: Fase 5 | B10: =COUNTIF(Matriz!$F$2:$F$105,$A10) | C10: =COUNTIFS(Matriz!$F$2:$F$105,$A10,Matriz!$L$2:$L$105,"Pendiente") | D10: =COUNTIFS(Matriz!$F$2:$F$105,$A10,Matriz!$L$2:$L$105,"En diseño") | E10: =COUNTIFS(Matriz!$F$2:$F$105,$A10,Matriz!$L$2:$L$105,"En desarrollo") | F10: =COUNTIFS(Matriz!$F$2:$F$105,$A10,Matriz!$L$2:$L$105,"En pruebas") | G10: =COUNTIFS(Matriz!$F$2:$F$105,$A10,Matriz!$L$2:$L$105,"Hecho") | H10: =COUNTIFS(Matriz!$F$2:$F$105,$A10,Matriz!$L$2:$L$105,"Bloqueado") | I10: =IF(B10=0,0,G10/B10)
A11: Transversal | B11: =COUNTIF(Matriz!$F$2:$F$105,$A11) | C11: =COUNTIFS(Matriz!$F$2:$F$105,$A11,Matriz!$L$2:$L$105,"Pendiente") | D11: =COUNTIFS(Matriz!$F$2:$F$105,$A11,Matriz!$L$2:$L$105,"En diseño") | E11: =COUNTIFS(Matriz!$F$2:$F$105,$A11,Matriz!$L$2:$L$105,"En desarrollo") | F11: =COUNTIFS(Matriz!$F$2:$F$105,$A11,Matriz!$L$2:$L$105,"En pruebas") | G11: =COUNTIFS(Matriz!$F$2:$F$105,$A11,Matriz!$L$2:$L$105,"Hecho") | H11: =COUNTIFS(Matriz!$F$2:$F$105,$A11,Matriz!$L$2:$L$105,"Bloqueado") | I11: =IF(B11=0,0,G11/B11)
A12: Total | B12: =SUM(B5:B11) | C12: =SUM(C5:C11) | D12: =SUM(D5:D11) | E12: =SUM(E5:E11) | F12: =SUM(F5:F11) | G12: =SUM(G5:G11) | H12: =SUM(H5:H11) | I12: =IF(B12=0,0,G12/B12)
A15: Hito | B15: Total | C15: Pendiente | D15: En diseño | E15: En desarrollo | F15: En pruebas | G15: Hecho | H15: Bloqueado | I15: % Hecho
A16: H1 · 18-oct (núcleo Fase 0) | B16: =COUNTIF(Matriz!$H$2:$H$105,$A16) | C16: =COUNTIFS(Matriz!$H$2:$H$105,$A16,Matriz!$L$2:$L$105,"Pendiente") | D16: =COUNTIFS(Matriz!$H$2:$H$105,$A16,Matriz!$L$2:$L$105,"En diseño") | E16: =COUNTIFS(Matriz!$H$2:$H$105,$A16,Matriz!$L$2:$L$105,"En desarrollo") | F16: =COUNTIFS(Matriz!$H$2:$H$105,$A16,Matriz!$L$2:$L$105,"En pruebas") | G16: =COUNTIFS(Matriz!$H$2:$H$105,$A16,Matriz!$L$2:$L$105,"Hecho") | H16: =COUNTIFS(Matriz!$H$2:$H$105,$A16,Matriz!$L$2:$L$105,"Bloqueado") | I16: =IF(B16=0,0,G16/B16)
A17: H2 · Fase 0 completa | B17: =COUNTIF(Matriz!$H$2:$H$105,$A17) | C17: =COUNTIFS(Matriz!$H$2:$H$105,$A17,Matriz!$L$2:$L$105,"Pendiente") | D17: =COUNTIFS(Matriz!$H$2:$H$105,$A17,Matriz!$L$2:$L$105,"En diseño") | E17: =COUNTIFS(Matriz!$H$2:$H$105,$A17,Matriz!$L$2:$L$105,"En desarrollo") | F17: =COUNTIFS(Matriz!$H$2:$H$105,$A17,Matriz!$L$2:$L$105,"En pruebas") | G17: =COUNTIFS(Matriz!$H$2:$H$105,$A17,Matriz!$L$2:$L$105,"Hecho") | H17: =COUNTIFS(Matriz!$H$2:$H$105,$A17,Matriz!$L$2:$L$105,"Bloqueado") | I17: =IF(B17=0,0,G17/B17)
A18: H3 · MVP (Grupos) | B18: =COUNTIF(Matriz!$H$2:$H$105,$A18) | C18: =COUNTIFS(Matriz!$H$2:$H$105,$A18,Matriz!$L$2:$L$105,"Pendiente") | D18: =COUNTIFS(Matriz!$H$2:$H$105,$A18,Matriz!$L$2:$L$105,"En diseño") | E18: =COUNTIFS(Matriz!$H$2:$H$105,$A18,Matriz!$L$2:$L$105,"En desarrollo") | F18: =COUNTIFS(Matriz!$H$2:$H$105,$A18,Matriz!$L$2:$L$105,"En pruebas") | G18: =COUNTIFS(Matriz!$H$2:$H$105,$A18,Matriz!$L$2:$L$105,"Hecho") | H18: =COUNTIFS(Matriz!$H$2:$H$105,$A18,Matriz!$L$2:$L$105,"Bloqueado") | I18: =IF(B18=0,0,G18/B18)
A19: Posterior | B19: =COUNTIF(Matriz!$H$2:$H$105,$A19) | C19: =COUNTIFS(Matriz!$H$2:$H$105,$A19,Matriz!$L$2:$L$105,"Pendiente") | D19: =COUNTIFS(Matriz!$H$2:$H$105,$A19,Matriz!$L$2:$L$105,"En diseño") | E19: =COUNTIFS(Matriz!$H$2:$H$105,$A19,Matriz!$L$2:$L$105,"En desarrollo") | F19: =COUNTIFS(Matriz!$H$2:$H$105,$A19,Matriz!$L$2:$L$105,"En pruebas") | G19: =COUNTIFS(Matriz!$H$2:$H$105,$A19,Matriz!$L$2:$L$105,"Hecho") | H19: =COUNTIFS(Matriz!$H$2:$H$105,$A19,Matriz!$L$2:$L$105,"Bloqueado") | I19: =IF(B19=0,0,G19/B19)
A20: Total | B20: =SUM(B16:B19) | C20: =SUM(C16:C19) | D20: =SUM(D16:D19) | E20: =SUM(E16:E19) | F20: =SUM(F16:F19) | G20: =SUM(G16:G19) | H20: =SUM(H16:H19) | I20: =IF(B20=0,0,G20/B20)
A23: Sprint | B23: Total | C23: Pendiente | D23: En diseño | E23: En desarrollo | F23: En pruebas | G23: Hecho | H23: Bloqueado | I23: % Hecho
A24: Sprint 0 | B24: =COUNTIF(Matriz!$G$2:$G$105,$A24) | C24: =COUNTIFS(Matriz!$G$2:$G$105,$A24,Matriz!$L$2:$L$105,"Pendiente") | D24: =COUNTIFS(Matriz!$G$2:$G$105,$A24,Matriz!$L$2:$L$105,"En diseño") | E24: =COUNTIFS(Matriz!$G$2:$G$105,$A24,Matriz!$L$2:$L$105,"En desarrollo") | F24: =COUNTIFS(Matriz!$G$2:$G$105,$A24,Matriz!$L$2:$L$105,"En pruebas") | G24: =COUNTIFS(Matriz!$G$2:$G$105,$A24,Matriz!$L$2:$L$105,"Hecho") | H24: =COUNTIFS(Matriz!$G$2:$G$105,$A24,Matriz!$L$2:$L$105,"Bloqueado") | I24: =IF(B24=0,0,G24/B24)
A25: Sprint 1 | B25: =COUNTIF(Matriz!$G$2:$G$105,$A25) | C25: =COUNTIFS(Matriz!$G$2:$G$105,$A25,Matriz!$L$2:$L$105,"Pendiente") | D25: =COUNTIFS(Matriz!$G$2:$G$105,$A25,Matriz!$L$2:$L$105,"En diseño") | E25: =COUNTIFS(Matriz!$G$2:$G$105,$A25,Matriz!$L$2:$L$105,"En desarrollo") | F25: =COUNTIFS(Matriz!$G$2:$G$105,$A25,Matriz!$L$2:$L$105,"En pruebas") | G25: =COUNTIFS(Matriz!$G$2:$G$105,$A25,Matriz!$L$2:$L$105,"Hecho") | H25: =COUNTIFS(Matriz!$G$2:$G$105,$A25,Matriz!$L$2:$L$105,"Bloqueado") | I25: =IF(B25=0,0,G25/B25)
A26: Sprint 2 | B26: =COUNTIF(Matriz!$G$2:$G$105,$A26) | C26: =COUNTIFS(Matriz!$G$2:$G$105,$A26,Matriz!$L$2:$L$105,"Pendiente") | D26: =COUNTIFS(Matriz!$G$2:$G$105,$A26,Matriz!$L$2:$L$105,"En diseño") | E26: =COUNTIFS(Matriz!$G$2:$G$105,$A26,Matriz!$L$2:$L$105,"En desarrollo") | F26: =COUNTIFS(Matriz!$G$2:$G$105,$A26,Matriz!$L$2:$L$105,"En pruebas") | G26: =COUNTIFS(Matriz!$G$2:$G$105,$A26,Matriz!$L$2:$L$105,"Hecho") | H26: =COUNTIFS(Matriz!$G$2:$G$105,$A26,Matriz!$L$2:$L$105,"Bloqueado") | I26: =IF(B26=0,0,G26/B26)
A27: Sprint 3 | B27: =COUNTIF(Matriz!$G$2:$G$105,$A27) | C27: =COUNTIFS(Matriz!$G$2:$G$105,$A27,Matriz!$L$2:$L$105,"Pendiente") | D27: =COUNTIFS(Matriz!$G$2:$G$105,$A27,Matriz!$L$2:$L$105,"En diseño") | E27: =COUNTIFS(Matriz!$G$2:$G$105,$A27,Matriz!$L$2:$L$105,"En desarrollo") | F27: =COUNTIFS(Matriz!$G$2:$G$105,$A27,Matriz!$L$2:$L$105,"En pruebas") | G27: =COUNTIFS(Matriz!$G$2:$G$105,$A27,Matriz!$L$2:$L$105,"Hecho") | H27: =COUNTIFS(Matriz!$G$2:$G$105,$A27,Matriz!$L$2:$L$105,"Bloqueado") | I27: =IF(B27=0,0,G27/B27)
A28: Sprint 4 | B28: =COUNTIF(Matriz!$G$2:$G$105,$A28) | C28: =COUNTIFS(Matriz!$G$2:$G$105,$A28,Matriz!$L$2:$L$105,"Pendiente") | D28: =COUNTIFS(Matriz!$G$2:$G$105,$A28,Matriz!$L$2:$L$105,"En diseño") | E28: =COUNTIFS(Matriz!$G$2:$G$105,$A28,Matriz!$L$2:$L$105,"En desarrollo") | F28: =COUNTIFS(Matriz!$G$2:$G$105,$A28,Matriz!$L$2:$L$105,"En pruebas") | G28: =COUNTIFS(Matriz!$G$2:$G$105,$A28,Matriz!$L$2:$L$105,"Hecho") | H28: =COUNTIFS(Matriz!$G$2:$G$105,$A28,Matriz!$L$2:$L$105,"Bloqueado") | I28: =IF(B28=0,0,G28/B28)
A29: Sprint 5 | B29: =COUNTIF(Matriz!$G$2:$G$105,$A29) | C29: =COUNTIFS(Matriz!$G$2:$G$105,$A29,Matriz!$L$2:$L$105,"Pendiente") | D29: =COUNTIFS(Matriz!$G$2:$G$105,$A29,Matriz!$L$2:$L$105,"En diseño") | E29: =COUNTIFS(Matriz!$G$2:$G$105,$A29,Matriz!$L$2:$L$105,"En desarrollo") | F29: =COUNTIFS(Matriz!$G$2:$G$105,$A29,Matriz!$L$2:$L$105,"En pruebas") | G29: =COUNTIFS(Matriz!$G$2:$G$105,$A29,Matriz!$L$2:$L$105,"Hecho") | H29: =COUNTIFS(Matriz!$G$2:$G$105,$A29,Matriz!$L$2:$L$105,"Bloqueado") | I29: =IF(B29=0,0,G29/B29)
A30: — | B30: =COUNTIF(Matriz!$G$2:$G$105,$A30) | C30: =COUNTIFS(Matriz!$G$2:$G$105,$A30,Matriz!$L$2:$L$105,"Pendiente") | D30: =COUNTIFS(Matriz!$G$2:$G$105,$A30,Matriz!$L$2:$L$105,"En diseño") | E30: =COUNTIFS(Matriz!$G$2:$G$105,$A30,Matriz!$L$2:$L$105,"En desarrollo") | F30: =COUNTIFS(Matriz!$G$2:$G$105,$A30,Matriz!$L$2:$L$105,"En pruebas") | G30: =COUNTIFS(Matriz!$G$2:$G$105,$A30,Matriz!$L$2:$L$105,"Hecho") | H30: =COUNTIFS(Matriz!$G$2:$G$105,$A30,Matriz!$L$2:$L$105,"Bloqueado") | I30: =IF(B30=0,0,G30/B30)
A31: Total | B31: =SUM(B24:B30) | C31: =SUM(C24:C30) | D31: =SUM(D24:D30) | E31: =SUM(E24:E30) | F31: =SUM(F24:F30) | G31: =SUM(G24:G30) | H31: =SUM(H24:H30) | I31: =IF(B31=0,0,G31/B31)
A34: Validación de requerimientos
A35: VoBo pendiente | B35: =COUNTIF(Matriz!$K$2:$K$105,A35)
A36: Aprobado | B36: =COUNTIF(Matriz!$K$2:$K$105,A36)
A37: Por definir | B37: =COUNTIF(Matriz!$K$2:$K$105,A37)
A38: Rechazado | B38: =COUNTIF(Matriz!$K$2:$K$105,A38)

Sheet Matriz
A1: ID | B1: Módulo | C1: Requerimiento | D1: Origen | E1: Alcance | F1: Fase | G1: Sprint | H1: Hito | I1: Historia de usuario (borrador) | J1: Criterio de aceptación / prueba (borrador) | K1: Validación | L1: Estado | M1: Evidencia | N1: Notas
A2: CFG-01 | B2: Configuración (low-code) | C2: Diseñador de formularios: crear, editar y deshabilitar campos en peticiones de oración y en los datos del expediente. Versión básica con tipos de campo comunes. | D2: v3 + Obs. 2 | E2: MVP | F2: Fase 0 | G2: Sprint 2 | H2: H2 · Fase 0 completa | I2: Como administrador quiero crear y editar formularios sin programar para adaptar peticiones y datos del expediente. | J2: Crear un formulario con los tipos de campo básicos, guardarlo, deshabilitar un campo y comprobar que las respuestas previas se conservan. | K2: VoBo pendiente | L2: Pendiente
A3: CFG-02 | B3: Configuración (low-code) | C3: Layouts y pantallas customizables: vistas, secciones visibles y tableros según rol o departamento. | D3: v2 | E3: Fuera del MVP | F3: Fase 5 | G3: — | H3: Posterior | I3: Se define al iniciar la fase. | J3: Se define al iniciar la fase. | K3: VoBo pendiente | L3: Pendiente
A4: CFG-03 | B4: Configuración (low-code) | C4: Gestor de flujos y permisos: creación de roles, niveles de acceso y reglas de negocio desde un panel visual. | D4: v2 | E4: Fuera del MVP | F4: Fase 5 | G4: — | H4: Posterior | I4: Se define al iniciar la fase. | J4: Se define al iniciar la fase. | K4: VoBo pendiente | L4: Pendiente
A5: CFG-04 | B5: Configuración (low-code) | C5: Plantillas de notificación editables (avisos, recordatorios de reunión, activación de cuenta). | D5: v3 | E5: MVP básico | F5: Fase 0 | G5: Sprint 2 | H5: H2 · Fase 0 completa | I5: Como administrador quiero editar los mensajes automáticos para ajustar el tono sin depender de TI. | J5: Editar una plantilla y verificar que el siguiente aviso usa el texto nuevo. | K5: VoBo pendiente | L5: Pendiente
A6: CFG-05 | B6: Configuración (low-code) | C6: Configurabilidad incremental: formularios primero; layouts y flujos avanzados después. | D6: v3 | E6: MVP | F6: Fase 0 | G6: Sprint 2 | H6: H2 · Fase 0 completa | I6: Como equipo queremos entregar la configurabilidad por fases para reducir riesgo. | J6: El diseñador de formularios está disponible en el MVP; layouts y flujos avanzados quedan en el backlog de Fase 5. | K6: VoBo pendiente | L6: Pendiente
A7: CFG-06 | B7: Configuración (low-code) | C7: Modelo híbrido de formularios: tablas fijas para las entidades principales (Persona/EDU, Grupo, Reunión, Ofrenda) con campos personalizados añadidos por el diseñador, y formularios independientes cuyas respuestas se guardan de forma flexible. | D7: Obs. 2 | E7: MVP | F7: Fase 0 | G7: Sprint 2 | H7: H2 · Fase 0 completa | I7: Como administrador quiero agregar campos personalizados a Persona, Grupo y Reunión para registrar lo que la iglesia necesita. | J7: Agregar un campo (ej. talla) a Persona; aparece en el formulario y se guarda sin alterar la estructura de la base. | K7: VoBo pendiente | L7: Pendiente
A8: CFG-07 | B8: Configuración (low-code) | C8: Campos de tipo «relación» (Persona/EDU, Grupo, Área) que conservan el vínculo por ID, para que reportes y estadísticas crucen formularios. | D8: Obs. 2 | E8: MVP | F8: Fase 0 | G8: Sprint 2 | H8: H2 · Fase 0 completa | I8: Como administrador quiero campos que apunten a una Persona o Grupo para cruzar datos en reportes. | J8: Un campo de relación guarda el ID de la Persona y el reporte lo cruza con su grupo. | K8: VoBo pendiente | L8: Pendiente
A9: CFG-08 | B9: Configuración (low-code) | C9: Un campo nunca se borra, solo se deshabilita. Cada cambio del formulario genera versión. Los campos «reportables» se marcan para consultas y estadísticas. | D9: Obs. 2 | E9: MVP | F9: Fase 0 | G9: Sprint 2 | H9: H2 · Fase 0 completa | I9: Como administrador quiero versionar los formularios para no perder respuestas antiguas. | J9: Deshabilitar un campo no borra respuestas; cada cambio crea versión; un campo reportable aparece en reportes. | K9: VoBo pendiente | L9: Pendiente
A10: M1-01 | B10: M1 Identidad y comunicación | C10: Expediente Digital Único (EDU) con los campos de la «Radiografía de miembros GC»: foto; nombre, apellidos, fecha de nacimiento (la edad se calcula); calle y número, colonia, código postal, alcaldía; teléfono fijo y celular; correo; grupo de conexión, líder y sector (texto provisional hasta el módulo de Grupos); tiempo en Mundo de Fe; ministerios en que sirve; devocional personal; Oración de Familias en Acción; otros cursos y observaciones. La foto se guarda en una carpeta del servidor con su ruta en la base de datos y solo se ve con sesión y permisos. | D10: v3 + Radiografía | E10: MVP | F10: Fase 0 | G10: Sprint 1 | H10: H1 · 18-oct (núcleo Fase 0) | I10: Como pastor quiero un expediente por persona con los datos de la Radiografía de miembros GC para conocer a mi gente. | J10: Crear un EDU con foto y los campos de la Radiografía, buscarlo sin importar acentos y consultarlo con el rol adecuado; la foto solo se ve con sesión. | K10: VoBo pendiente | L10: En pruebas | M10: Rama feature/m1-01-expediente · 56 pruebas de backend y 6 de frontend pasan | N10: 2026-10-05 · Falta revisar con la iglesia que los campos y el orden de la Radiografía estén completos.
A11: M1-02 | B11: M1 Identidad y comunicación | C11: Los datos que se recaban en el EDU son configurables. | D11: v3 | E11: MVP | F11: Fase 0 | G11: Sprint 2 | H11: H2 · Fase 0 completa | I11: Como administrador quiero definir qué datos se recaban en el expediente. | J11: Agregar un campo configurable al EDU y verlo en el alta (depende de CFG-06). | K11: VoBo pendiente | L11: Pendiente
A12: M1-03 | B12: M1 Identidad y comunicación | C12: Vínculo familiar y tutor–menor en el expediente, y lista de personas autorizadas a recoger a cada menor (insumo del módulo Kids). | D12: Nuevo v3 | E12: Fuera del MVP | F12: Fase 2 | G12: — | H12: Posterior | I12: Se define al iniciar la fase. | J12: Se define al iniciar la fase. | K12: VoBo pendiente | L12: Pendiente
A13: M1-04 | B13: M1 Identidad y comunicación | C13: Registro de bienes: vehículos y motos (placas, marca, modelo, color) u otros bienes personales traídos a la iglesia, asociados al expediente. | D13: v2 | E13: Fuera del MVP | F13: Fase 5 | G13: — | H13: Posterior | I13: Se define al iniciar la fase. | J13: Se define al iniciar la fase. | K13: VoBo pendiente | L13: Pendiente
A14: M1-05 | B14: M1 Identidad y comunicación | C14: Alertas rápidas: el personal de seguridad o ushers busca una placa y envía una notificación push prioritaria al propietario (auto mal estacionado, acceso bloqueado, etc.). | D14: v2 | E14: Fuera del MVP | F14: Fase 5 | G14: — | H14: Posterior | I14: Se define al iniciar la fase. | J14: Se define al iniciar la fase. | K14: VoBo pendiente | L14: Pendiente
A15: M1-06 | B15: M1 Identidad y comunicación | C15: Canal de respaldo para alertas cuando el propietario no tiene la app instalada o no concedió permisos de notificación (p. ej. WhatsApp o SMS). Por definir canal. | D15: Nuevo v3 | E15: Fuera del MVP | F15: Fase 5 | G15: — | H15: Posterior | I15: Se define al iniciar la fase. | J15: Se define al iniciar la fase. | K15: Por definir | L15: Pendiente
A16: M1-07 | B16: M1 Identidad y comunicación | C16: RBAC configurable con la jerarquía: Administrador Técnico, Pastor General, Ancianos (como Pastor, con limitantes en finanzas), Directores/Supervisores, Líderes/Maestros, Servidores, Miembro/Asistente. | D16: v3 + Resp. P8 | E16: MVP | F16: Fase 0 | G16: Sprint 1 | H16: H1 · 18-oct (núcleo Fase 0) | I16: Como administrador quiero asignar roles con la jerarquía acordada para controlar accesos. | J16: Un Líder no accede a otro grupo; los Ancianos no ven finanzas; el Pastor ve todo. | K16: VoBo pendiente | L16: En pruebas | M16: Rama feature/paso-6-roles-permisos · pruebas de backend y 97 de frontend pasan; lint, estilos y compilación limpios | N16: 2026-10-29 · Roles base más la Secretaria; asignación con jerarquía (nadie otorga un rol más alto que el suyo, solo el Super Usuario asigna Super Usuario); baja y traslado solo por un superior.
A17: M1-08 | B17: M1 Identidad y comunicación | C17: Permisos por área y por grupo. Requiere un catálogo mínimo de áreas (ver M5-01). | D17: v3 | E17: MVP | F17: Fase 0 | G17: Sprint 1 | H17: H2 · Fase 0 completa | I17: Como director quiero permisos por área o grupo para acotar lo que ve cada servidor. | J17: Un permiso por grupo permite ver solo ese grupo. | K17: VoBo pendiente | L17: En pruebas | M17: Rama feature/m3-grupos · 88 pruebas de backend y 7 de frontend pasan | N17: 2026-10-24 · Alcance por grupo implementado en el módulo Grupos.
A18: M1-09 | B18: M1 Identidad y comunicación | C18: Avisos globales y notificaciones push segmentables por audiencia. | D18: v3 | E18: MVP | F18: Fase 0 | G18: Sprint 2 | H18: H2 · Fase 0 completa | I18: Como pastor quiero enviar avisos segmentados para llegar a la audiencia correcta. | J18: Enviar un aviso a un grupo y verificar que solo sus integrantes lo reciben. | K18: VoBo pendiente | L18: En pruebas | M18: Rama feature/m1-09-notificaciones · pruebas de backend y 66 de frontend pasan; claves VAPID de QA configuradas | N18: 2026-10-26 · Notificaciones push con sonido y vibración para mensajes del tablero y estudio nuevo, solo a quien puede leerlos; se activan por dispositivo y se pueden apagar en Configuración. Pendiente: probar en Samsung S23 e iPhone reales y los avisos de la iglesia en general (no ligados a un grupo).
A19: M1-10 | B19: M1 Identidad y comunicación | C19: Los avisos no son públicos. El visitante recibe por WhatsApp un enlace a un espacio con rol «Visitante» donde consulta avisos y eventos. | D19: v3 + Resp. P8 | E19: MVP | F19: Fase 0 | G19: Sprint 2 | H19: H2 · Fase 0 completa | I19: Como visitante quiero consultar avisos y eventos desde un enlace sin ser miembro. | J19: Un Contacto abre el enlace de WhatsApp y ve avisos con rol Visitante, sin acceso a otros datos. | K19: VoBo pendiente | L19: En pruebas | M19: Rama feature/paso-5-invitaciones · pruebas de backend y 93 de frontend pasan; lint, estilos y compilación limpios | N19: 2026-10-27 · Rol por defecto Miembro / Asistente al invitar; invitación por enlace o QR con aprobación del líder (sala de espera) y asignación manual desde la ficha de la persona, con notificaciones.
A20: M1-11 | B20: M1 Identidad y comunicación | C20: Aviso de privacidad y consentimiento al registrar a cualquier persona o activar una cuenta, con consentimiento aparte para la foto. Cada consentimiento guarda la versión del aviso y la fecha. Por ahora el texto es genérico de ejemplo y debe sustituirse por el oficial antes de producción. | D20: v3 | E20: MVP | F20: Fase 0 | G20: Sprint 1 | H20: H1 · 18-oct (núcleo Fase 0) | I20: Como persona registrada quiero conocer y aceptar el aviso de privacidad. | J20: No se guarda un registro sin consentimiento; queda versión del aviso, fecha y alcance (foto, menores). | K20: VoBo pendiente | L20: En pruebas | M20: Rama feature/m1-01-expediente · 56 pruebas de backend y 6 de frontend pasan | N20: 2026-10-05 · Texto del aviso genérico; sustituir por el oficial antes de producción.
A21: M1-12 | B21: M1 Identidad y comunicación | C21: Tres niveles de registro: Contacto (nombre, WhatsApp, procedencia, consentimiento), Participante y EDU completo. Un Contacto puede ascender a EDU sin duplicarse; el número de WhatsApp sirve para detectar duplicados. | D21: Obs. 3 y 10 | E21: MVP | F21: Fase 0 | G21: Sprint 1 | H21: H1 · 18-oct (núcleo Fase 0) | I21: Como encargado de bienvenida quiero registrar a un visitante con nombre y WhatsApp para darle seguimiento. | J21: Registrar un Contacto; al ascender a EDU no se duplica; el mismo WhatsApp detecta duplicado. | K21: VoBo pendiente | L21: En pruebas | M21: Rama feature/personas-paso-4 · pruebas de backend y 85 de frontend pasan; lint, estilos y compilación limpios | N21: 2026-10-27 · Niveles contacto → participante → expediente completo, ahora explicados en la ficha; duplicados por WhatsApp.
A22: M1-13 | B22: M1 Identidad y comunicación | C22: Atributo de procedencia: miembro de la iglesia local, invitado de grupo (no asiste a la iglesia), visitante de la iglesia o externo. | D22: Obs. 3 | E22: MVP | F22: Fase 0 | G22: Sprint 1 | H22: H1 · 18-oct (núcleo Fase 0) | I22: Como pastor quiero saber la procedencia de cada persona. | J22: Valores: miembro, invitado de grupo, visitante y externo; se puede filtrar en listas. | K22: VoBo pendiente | L22: En pruebas | M22: Rama feature/m1-01-expediente · 56 pruebas de backend y 6 de frontend pasan | N22: 2026-10-05 · Procedencia en el alta y en la ficha.
A23: M1-14 | B23: M1 Identidad y comunicación | C23: Bitácora de movimientos del EDU: altas, bajas, cambios de grupo o área, con fecha y motivo. Al dejar la iglesia solo se conservan fecha y motivo. | D23: Resp. P8 | E23: MVP | F23: Fase 0 | G23: Sprint 1 | H23: H1 · 18-oct (núcleo Fase 0) | I23: Como pastor quiero un historial de altas, bajas y cambios con fecha y motivo. | J23: Una baja conserva solo fecha y motivo; el movimiento aparece en el historial del EDU. | K23: VoBo pendiente | L23: En pruebas | M23: Rama feature/personas-paso-4 · pruebas de backend y 85 de frontend pasan; lint, estilos y compilación limpios | N23: 2026-10-27 · Historial de movimientos con fecha y motivo; ahora incluye traslado a otra iglesia con su destino, y la baja retira a la persona de sus grupos.
A24: M1-16 | B24: M1 Identidad y comunicación | C24: Control de modificaciones: solo roles definidos pueden modificar datos sensibles (ofrendas, asistencias). Toda consulta o modificación queda en bitácora. | D24: Obs. 5 | E24: MVP | F24: Fase 0 | G24: Sprint 1 | H24: H1 · 18-oct (núcleo Fase 0) | I24: Como pastor quiero que solo ciertos roles modifiquen datos sensibles. | J24: Modificar una asistencia o una ofrenda exige rol autorizado y motivo, y queda en bitácora. | K24: VoBo pendiente | L24: En pruebas | M24: Rama feature/navegacion-dashboard-paso-2 · pruebas de backend y 77 de frontend pasan; lint, estilos y compilación limpios | N24: 2026-10-27 · Bitácora con niveles tipo semáforo, filtros, paginación y gráfica de errores por día. Consultar el resumen también exige el permiso de bitácora.
A25: M1-17 | B25: M1 Identidad y comunicación | C25: Acceso con número de WhatsApp o correo y PIN de 6 dígitos (contraseña de 10+ caracteres para roles sensibles como Pastor, Tesorero y Administrador). La cuenta se activa con un enlace de un solo uso que caduca, enviado desde el WhatsApp de quien invita (sin costo). Recuperación: reinicio por Líder o administrador y enlace por correo si lo tiene. Sin SMS en el MVP. | D25: Nuevo v3.1 / v3.3 | E25: MVP | F25: Fase 0 | G25: Sprint 0 | H25: H1 · 18-oct (núcleo Fase 0) | I25: Como usuario quiero entrar con mi WhatsApp o correo y un PIN sencillo. | J25: Activar la cuenta con enlace de un solo uso, entrar con PIN de 6 dígitos (contraseña fuerte en roles sensibles), bloqueo tras 5 intentos y recuperación por Líder, administrador o correo. | K25: VoBo pendiente | L25: Hecho | M25: Rama feature/m1-17-acceso · 33 pruebas de backend y 4 de frontend pasan · Flujo invitar, activar y entrar probado por Edgar en navegador de escritorio | N25: 2026-10-05 · Pendiente repetir la prueba en Android/iOS (se cubre con NF-07).
A26: M1-18 | B26: M1 Identidad y comunicación | C26: Contacto de seguimiento a visitantes: un responsable asignado y estado (nuevo, contactado, invitado a consolidación, se integró, no continuó). | D26: Obs. 10 | E26: MVP mínimo | F26: Fase 0 | G26: Sprint 2 | H26: H2 · Fase 0 completa | I26: Como responsable de seguimiento quiero ver a quién contactar y en qué estado va. | J26: Un Contacto tiene responsable y estado; cada cambio de estado queda registrado. | K26: VoBo pendiente | L26: Pendiente
A27: M1-19 | B27: M1 Identidad y comunicación | C27: Dashboard y tablero de mensajes por módulo como componentes genéricos: el tablero (y las peticiones) se registran por origen y cada módulo decide quién publica y quién lee; los gráficos del dashboard viven en el sistema de diseño. Grupos de Conexión es el primer módulo en usarlos. | D27: Obs. 7 | E27: MVP | F27: Fase 0 | G27: Sprint 5 | H27: H3 · MVP (Grupos) | I27: Como líder o supervisor quiero un dashboard y un tablero de mensajes en mi módulo. | J27: El módulo Grupos muestra dashboard y tablero con permisos por rol. | K27: VoBo pendiente | L27: En pruebas | M27: Rama feature/navegacion-dashboard-paso-2 · pruebas de backend y 77 de frontend pasan; lint, estilos y compilación limpios | N27: 2026-10-27 · Tablero y gráficas como componentes genéricos; grupos es el primer origen. Barra superior con Cerrar sesión, menú por categorías, Inicio como dashboard con accesos rápidos y resumen de grupos, y color de la aplicación elegible (v3.15).
A28: M1-21 | B28: M1 Identidad y comunicación | C28: Cambio de número: el usuario lo actualiza con su PIN actual, el Líder recibe un aviso y queda en bitácora. Si perdió número y teléfono, el Líder o administrador reinicia su acceso. La identidad estable es un ID interno, no el número. El aviso al Líder se activa cuando exista el módulo de Grupos. | D28: Nuevo v3.3 | E28: MVP | F28: Fase 0 | G28: Sprint 1 | H28: H1 · 18-oct (núcleo Fase 0) | I28: Como persona que cambió de número quiero actualizarlo sin perder mi historial. | J28: Cambio con el PIN actual, aviso al Líder y registro en bitácora; si perdió número y teléfono, el Líder o administrador reinicia el acceso. | K28: VoBo pendiente | L28: En pruebas | M28: Rama feature/m1-17-acceso · 33 pruebas de backend y 4 de frontend pasan | N28: 2026-10-05 · El aviso al Líder se activa cuando exista Grupos (Sprint 3).
A29: M1-22 | B29: M1 Identidad y comunicación | C29: Bloqueo de cuenta tras 5 intentos fallidos durante 15 minutos (configurable), limitación de intentos por IP y sesión de 90 días renovable con el uso. | D29: Nuevo v3.3 | E29: MVP | F29: Fase 0 | G29: Sprint 0 | H29: H1 · 18-oct (núcleo Fase 0) | I29: Como iglesia queremos proteger las cuentas de intentos de adivinar el PIN. | J29: Tras 5 intentos fallidos la cuenta se bloquea 15 minutos; sesión de 90 días renovable. | K29: VoBo pendiente | L29: En pruebas | M29: Rama feature/m1-17-acceso · 33 pruebas de backend y 4 de frontend pasan | N29: 2026-10-05 · Límite de intentos por IP: 30 por minuto.
A30: M1-23 | B30: M1 Identidad y comunicación | C30: Procesos de desarrollo discipular: catálogo configurable (14 procesos de la Radiografía: Nacimiento Espiritual, Consolidación, Peniel, Bautismo en el Espíritu Santo, Bautismo en Agua, Sanidad Total, Fundamentos de la Vida Cristiana, Fundamentos Doctrinales, Fundamentos de Liderazgo, Avanzado hacia la Meta, Visión G. de Conexión, Espíritu Santo, Panorama Bíblico y Lanzamiento) y avance por persona con fecha y nombre del maestro. | D30: Nuevo v3.4 | E30: MVP | F30: Fase 0 | G30: Sprint 1 | H30: H1 · 18-oct (núcleo Fase 0) | I30: Como líder quiero registrar los procesos de discipulado que ha cursado cada persona, con fecha y maestro. | J30: Marcar procesos del catálogo con fecha y maestro, guardarlos y verlos en la ficha; el catálogo es configurable. | K30: VoBo pendiente | L30: En pruebas | M30: Rama feature/m1-01-expediente · 56 pruebas de backend y 6 de frontend pasan | N30: 2026-10-05 · 14 procesos sembrados desde la Radiografía.
A31: M1-24 | B31: M1 Identidad y comunicación | C31: Administrador de roles y permisos: se crean roles y, por módulo, pantalla y acción, se elige lo que cada uno puede hacer. El Super Usuario, el Pastor y la Secretaria lo administran; nadie está por encima del Super Usuario y solo él asigna ese rol. Nadie concede un permiso que no tiene ni crea o cambia un rol de su nivel o superior. Un rol en uso no se desactiva y todo cambio queda en bitácora. | D31: Respuesta v3.19 | E31: MVP | F31: Fase 0 | G31: Sprint 5 | H31: H2 · Fase 0 completa | I31: Como administrador quiero crear roles y elegir, por módulo, pantalla y acción, lo que puede hacer cada uno, para que los permisos no se hagan bolas. | J31: Crear un rol con permisos, no poder conceder los que no se tienen ni editar un rol de nivel igual o superior, y ver en la bitácora quién cambió qué. | K31: VoBo pendiente | L31: En pruebas | M31: Rama feature/paso-6-roles-permisos · pruebas de backend y 97 de frontend pasan; lint, estilos y compilación limpios | N31: 2026-10-29 · Catálogo de permisos, pantalla de roles con matriz, duplicado y desactivación, rol Secretaria y vista de lo que puede hacer cada persona. Falta: roles de unidad con alcance (siguiente entrega).
A32: M1-25 | B32: M1 Identidad y comunicación | C32: Ministerios: áreas de servicio de la iglesia (cafetería, librería, niños, danza, etc.), cada uno con encargado, respaldo y servidores. Quien participa en un ministerio ve solo ese ministerio, y su rol vale únicamente dentro de él, independiente de sus roles en grupos u otros ministerios. Cada ministerio tiene su propio tablero de avisos y sus peticiones de oración. | D32: Respuesta v3.21 | E32: MVP | F32: Fase 0 | G32: Sprint 5 | H32: H2 · Fase 0 completa | I32: Como encargado de un ministerio quiero administrar a mi gente y mis avisos sin ver lo de otros ministerios ni grupos. | J32: Un encargado de la cafetería no ve la librería; el mismo encargado como asistente de un grupo no gestiona ese grupo; un servidor no agrega integrantes. | K32: VoBo pendiente | L32: En pruebas | M32: Rama feature/paso-8-ministerios-mi-cuenta · pruebas de backend y 108 de frontend pasan; lint, estilos y compilación limpios | N32: 2026-10-30 · Ministerios (antes unidades) con encargado, respaldo y servidores, alcance propio, tablero de avisos y peticiones de oración.
A33: M1-26 | B33: M1 Identidad y comunicación | C33: Roles de grupos y de ministerios configurables: encargado (líder en un grupo), respaldo y servidores, además de los roles que ya existían. Quien administra roles (Super Usuario, Pastor y Secretaria) crea roles y elige, por acción, lo que puede hacer quien los tiene dentro de un grupo o de un ministerio. | D33: Respuesta v3.21 | E33: MVP | F33: Fase 0 | G33: Sprint 5 | H33: H2 · Fase 0 completa | I33: Como administrador quiero definir qué puede hacer el encargado, el respaldo y los servidores de cada grupo y ministerio, para no depender de reglas fijas. | J33: Crear un rol de ministerio con permisos; quitarle un permiso al encargado cambia lo que puede hacer; un rol que administra gente solo lo asigna la administración; un rol base no se desactiva. | K33: VoBo pendiente | L33: En pruebas | M33: Rama feature/paso-8-ministerios-mi-cuenta · pruebas de backend y 108 de frontend pasan; lint, estilos y compilación limpios | N33: 2026-10-30 · Roles de ministerio y de grupo configurables desde Roles y permisos; roles base y roles nuevos; las ofrendas y peticiones de grupo siguen con reglas fijas.
A34: M1-27 | B34: M1 Identidad y comunicación | C34: Mi cuenta: la persona corrige sus datos básicos (nombre, fecha de nacimiento, domicilio, teléfono fijo, devocional, oración de familias y foto). No edita nada que afecte su acceso (WhatsApp, correo, PIN) ni sus relaciones con la iglesia (grupo, sector, ministerios, roles, nivel). | D34: Respuesta v3.21 | E34: MVP | F34: Fase 0 | G34: Sprint 5 | H34: H2 · Fase 0 completa | I34: Como persona quiero corregir mis datos básicos desde Mi cuenta sin poder cambiar mi acceso ni mi grupo. | J34: Corregir nombre y domicilio; intentar cambiar WhatsApp, correo, nivel o grupo no tiene efecto; la foto pide aceptar su uso; la bitácora no guarda los valores. | K34: VoBo pendiente | L34: En pruebas | M34: Rama feature/paso-8-ministerios-mi-cuenta · pruebas de backend y 108 de frontend pasan; lint, estilos y compilación limpios | N34: 2026-10-30 · Mi cuenta editable: datos básicos y foto con consentimiento; sin acceso ni relaciones.
A35: M1-28 | B35: M1 Identidad y comunicación | C35: Peticiones de oración personales: toda persona con sesión puede pedir oración y ve la sección de oración. Ve las suyas; las ve también la dirección que consulta todas las peticiones, y el equipo de oración si las comparte con él. | D35: Respuesta v3.22 | E35: MVP | F35: Fase 0 | G35: Sprint 5 | H35: H2 · Fase 0 completa | I35: Como persona quiero pedir oración desde la aplicación y ver mis peticiones. | J35: Cualquier cuenta registra una petición personal y la ve; otra cuenta no; el equipo de oración solo lee las compartidas con él. | K35: VoBo pendiente | L35: En pruebas | M35: Rama feature/paso-9-oraciones-vehiculos · pruebas de backend y 110 de frontend pasan; lint, estilos y compilación limpios | N35: 2026-10-30 · Origen de peticiones personales para toda cuenta.
A36: M1-29 | B36: M1 Identidad y comunicación | C36: Bienes ligados (vehículos): cada persona registra, corrige y quita sus vehículos (tipo, marca, modelo, año, color y placas) desde Mi cuenta. Quien consulta expedientes los ve en la ficha, sin poder cambiarlos. | D36: Respuesta v3.22 | E36: MVP | F36: Fase 0 | G36: Sprint 5 | H36: H2 · Fase 0 completa | I36: Como persona quiero registrar mis vehículos para que la iglesia los conozca. | J36: Agregar, editar y quitar un vehículo propio; no se puede tocar el de otra persona; queda en la bitácora. | K36: VoBo pendiente | L36: En pruebas | M36: Rama feature/paso-9-oraciones-vehiculos · pruebas de backend y 110 de frontend pasan; lint, estilos y compilación limpios | N36: 2026-10-30 · Vehículos propios en Mi cuenta y consulta en la ficha.
A37: M2A-01 | B37: M2A Cursos de Vida | C37: Catálogo dinámico de cursos; se pueden crear nuevos sin intervención técnica. Incluye «Resolución de Varones» y «Toma de Buenas Decisiones», omitidos en v2. | D37: Recuperado v1 | E37: Fuera del MVP | F37: Fase 3 | G37: — | H37: Posterior | I37: Se define al iniciar la fase. | J37: Se define al iniciar la fase. | K37: VoBo pendiente | L37: Pendiente
A38: M2A-02 | B38: M2A Cursos de Vida | C38: Flexibilidad operativa: sin día ni horario fijo; el día y el ponente pueden cambiar entre ediciones. | D38: v1 / v2 | E38: Fuera del MVP | F38: Fase 3 | G38: — | H38: Posterior | I38: Se define al iniciar la fase. | J38: Se define al iniciar la fase. | K38: VoBo pendiente | L38: Pendiente
A39: M2A-03 | B39: M2A Cursos de Vida | C39: Reposición de clases: el inscrito puede reponer en otro grupo o con otro ponente, a decisión de quien imparte. | D39: v1 / v2 | E39: Fuera del MVP | F39: Fase 3 | G39: — | H39: Posterior | I39: Se define al iniciar la fase. | J39: Se define al iniciar la fase. | K39: VoBo pendiente | L39: Pendiente
A40: M2A-04 | B40: M2A Cursos de Vida | C40: Registro de asistencia por sesión. | D40: v1 / v2 | E40: Fuera del MVP | F40: Fase 3 | G40: — | H40: Posterior | I40: Se define al iniciar la fase. | J40: Se define al iniciar la fase. | K40: VoBo pendiente | L40: Pendiente
...

Sheet Observaciones
A1: Obs. | B1: Resumen de la observación | C1: Requerimientos | D1: Resolución | E1: Estado
A2: 1 | B2: ¿PWA o nativa? Considerar permisos, costos y usuarios mayores. | C2: NF-07, NF-10 | D2: PWA primero; lógica separada para envolver como app nativa si se justifica. | E2: Decidido
A3: 2 | B3: Diseñador dinámico con relaciones para reportes y estadísticas. | C3: CFG-06, CFG-07, CFG-08 | D3: Modelo híbrido: tablas fijas + campos personalizados + campos de relación. | E3: En MVP (Sprint 2)
A4: 3 | B4: Distinguir si el inscrito es de la iglesia local; pedir WhatsApp. | C4: M1-12, M1-13 | D4: Tres niveles de registro y atributo de procedencia. Su uso en cursos llega en Fase 3. | E4: En MVP (Sprint 1)
A5: 4 | B5: Tesorero con firma que avala la cifra. | C5: M3-01, M3-04 | D5: Rol Tesorero y aval electrónico simple con diferencia registrada. | E5: En MVP (Sprint 4)
A6: 5 | B6: Confidencialidad de ofrendas y asistencias, con bitácora. | C6: M1-16, M3-10 | D6: Matriz de confidencialidad aprobada (v3.2, sección 3.3). | E6: En MVP (Sprint 1 y 4)
A7: 6 | B7: Alternativa a M4-05: check-out sin teléfono. | C7: M4-05 | D7: Validación por el servidor del salón con fotos y bitácora. | E7: Fase 2
A8: 7 | B8: Dashboard y tablero de mensajes por módulo (se omiten los «roles de servir»). | C8: M1-19, M3-11 | D8: Componente genérico reutilizable. | E8: En MVP (Sprint 5)
A9: 8 | B9: Datos de salud en el EDU y medicamentos con caducidad. | C9: M6-07 y ficha de salud | D9: Fuera del MVP; el modelo del EDU se prepara para admitirlos. | E9: Posterior
A10: 9 | B10: Registro breve y seguimiento de personas nuevas. | C10: M1-12, M1-18, M3-09 | D10: Contacto con WhatsApp, responsable y estados. | E10: En MVP (Sprint 1 y 2)
A11: 10 | B11: Reserva de lugares y sobrecupo autorizado en eventos. | C11: M7-04 | D11: Reserva por cantidad y sobrecupo con autorización y bitácora. | E11: Fase 4
A12: P8-1 | B12: Respuestas: Ancianos como Pastor, con limitantes en finanzas. | C12: M1-07 | D12: Incorporado en RBAC y en la matriz de confidencialidad. | E12: En MVP (Sprint 1)
... A31: P1-12 | B31: Pruebas 1: el rol de Super Usuario es el único que asigna Administrador técnico. | C31: M1-07 | D31: Confirmado por Edgar el 27-oct-2026; el sistema ya lo cumple (nadie otorga un rol más alto que el suyo) y hay prueba. | E31: Hecho (v3.15)

Sheet Origen v1
A1: Necesidad del levantamiento original (v1) | B1: Requerimientos actuales | C1: Situación | D1: Alcance
A2: Roles con permisos distintos por módulo (Pastor, ancianos, líderes, servidores) | B2: M1-07, M1-08 | C2: Cubierto | D2: MVP
A3: Cursos de vida: listas de asistencia | B3: M2A-04 | C3: Cubierto | D3: Fase 3
A4: Cursos de vida: control de tareas o actividades (no requerido) | B4: M2A-05 | C4: Cubierto | D4: Fase 3
A5: Cursos de vida: evolución del ponente | B5: M2A-10 | C5: Recuperado en v3 | D5: Fase 3
A6: Cursos de vida: anuncios y tablero tipo WhatsApp antes y después del curso | B6: M2A-08 | C6: Recuperado en v3 | D6: Fase 3
A7: Cursos de vida: inscripción, adeudo y qué incluye el costo | B7: M2A-06, M2A-07 | C7: Cubierto | D7: Fase 3
A8: Cursos de vida: cambio de día, ponente y reposición de clases | B8: M2A-02, M2A-03 | C8: Cubierto | D8: Fase 3
A9: Cursos de vida: evaluación de ponentes diseñable (tipo Google Forms) | B9: M2A-09, CFG-01 | C9: Cubierto | D9: Fase 3
A10: Cursos de vida: reconocimiento opcional | B10: M2A-11 | C10: Cubierto | D10: Fase 3
A11: Cursos «Resolución de varones» y «Toma de buenas decisiones» | B11: M2A-01 | C11: Recuperado en v3 | D11: Fase 3
A12: Cursos escolarizados: asistencia, tareas, calificación, exámenes y boleta con formato | B12: M2B-01 a M2B-06 | C12: Cubierto | D12: Fase 3
... A27: Grupos de conexión: el supervisor reporta al Pastor | B27: M3-01, M3-07 | C27: Cubierto | D27: MVP
